Exception:
Traceback (most recent call last):
  File "/home/skylar/pinax/pinax-env/lib/python2.6/site-packages/pip-0.4-py2.6.egg/pip.py", line 274, in main
    self.run(options, args)
  File "/home/skylar/pinax/pinax-env/lib/python2.6/site-packages/pip-0.4-py2.6.egg/pip.py", line 429, in run
    for req in parse_requirements(filename, finder=finder):
  File "/home/skylar/pinax/pinax-env/lib/python2.6/site-packages/pip-0.4-py2.6.egg/pip.py", line 3359, in parse_requirements
    filename, content = get_file_content(filename, comes_from=comes_from)
  File "/home/skylar/pinax/pinax-env/lib/python2.6/site-packages/pip-0.4-py2.6.egg/pip.py", line 3350, in get_file_content
    f = open(url)
IOError: [Errno 2] No such file or directory: 'src/pinax/requirements/external_apps.txt'
